Workbook

Sheet Vista Pública
A1: Locos del Deporte — CrazySports (Grupo 6)
A2: Nombre del Módulo: Vista Pública
A3: ID | B3: Título | C3: HU | D3: RF | E3: Criterio de aceptación | F3: Técnica de diseño | G3: Descripción | H3: Precondiciones | I3: Datos de prueba | J3: Pasos | K3: Resultado esperado | L3: Postcondición / limpieza | M3: Status | N3: Prioridad | O3: #Etiquetas | P3: Evidencia (link) | Q3: Bug (link a Issue) | R3: Diseñado por | S3: Ejecutado por | T3: Fecha de ejecución | U3: Resultado obtenido | V3: Comentarios
A4: TC-VP-01 | B4: Ver listado de clubes aprobados sin login | C4: HU-01 | D4: RF-01 | E4: CA-1.1, CA-1.2, CA-1.3 | F4: Partición de equivalencia (aprobado / pendiente) | G4: Verificar que un visitante sin autenticarse ve solo los clubes aprobados | H4: 1. Docker (PostgreSQL :5432), backend (:8080) y frontend (:5173) levantados. 2. BD cargada con el conjunto DS-01 (ver Plan de Pruebas, sección Datos de Prueba Base). 3. Chrome sin sesión iniciada. | I4: Ninguno (se usa DS-01: 3 clubes aprobados y 2 pendientes) | J4: 1. Abrir Chrome. 2. Ir a http://localhost:5173/clubes. | K4: Se muestran exactamente 3 cards: «Club Atlético Río Tercero» (Av. San Martín 100, Fútbol), «Club Náutico Río Tercero» (Costanera 250, Natación) y «Club Atlético Sur» (Calle Belgrano 45, Básquet). No se muestran «Club Pendiente Uno» ni «Club Pendiente Dos». No se pide login. | L4: Ninguna (solo lectura). | M4: PASS | N4: Crítica | O4: #VistaPublica #Smoke #Regresion | P4: tc-vp-01.png | R4: Joaquin Brassinne | S4: Leonel López | T4: 46318 | U4: Se muestran 3 clubes: Club Sportivo 9 de Julio, Club Atlético Río Tercero y Polideportivo Municipal. No se pide login.
A5: TC-VP-02 | B5: Ver listado de deportistas aprobados sin login | C5: HU-02 | D5: RF-02 | E5: CA-2.1, CA-2.2, CA-2.3 | F5: Partición de equivalencia (aprobado / pendiente) | G5: Verificar que un visitante sin autenticarse ve solo los deportistas aprobados | H5: 1. Docker (PostgreSQL :5432), backend (:8080) y frontend (:5173) levantados. 2. BD cargada con el conjunto DS-01 (ver Plan de Pruebas, sección Datos de Prueba Base). 3. Chrome sin sesión iniciada. | I5: Ninguno (DS-01: 4 deportistas aprobados y 1 pendiente) | J5: 1. Abrir Chrome. 2. Ir a http://localhost:5173/deportistas. | K5: Se muestran exactamente 4 cards: Lucía Pérez (Fútbol, «Campeona Liga Regional 2025»), Mateo Gómez (Básquet, «MVP Torneo Provincial 2025»), Sofía Díaz (Fútbol, «Goleadora Copa Ciudad 2024») y Tomás Ruiz (Natación, «Medalla de plata 2025»). No se muestra «Valentina Cruz». No se pide login. | L5: Ninguna (solo lectura). | M5: PASS | N5: Crítica | O5: #VistaPublica #Smoke #Regresion | P5: tc-vp-02.png | R5: Joaquin Brassinne | S5: Leonel López | T5: 46318 | U5: Se muestran deportistas aprobados (visibles en la captura: Martina López, Carlos Méndez y Lucía Fernández). No se pide login.
A6: TC-VP-03 | B6: Buscar club por nombre | C6: HU-03 | D6: RF-03 | E6: CA-3.1 | F6: Partición de equivalencia (texto que coincide con parte de los clubes) | G6: Verificar que el buscador filtra clubes por nombre | H6: 1. Docker (PostgreSQL :5432), backend (:8080) y frontend (:5173) levantados. 2. BD cargada con el conjunto DS-01 (ver Plan de Pruebas, sección Datos de Prueba Base). | I6: nombre: Club Atlético | J6: 1. Ir a http://localhost:5173/clubes. 2. Escribir «Club Atlético» en el buscador. 3. Click en «Buscar». | K6: Se muestran exactamente 2 cards: «Club Atlético Río Tercero» y «Club Atlético Sur». No se muestra «Club Náutico Río Tercero». | L6: Ninguna. | M6: PASS | N6: Alta | O6: #VistaPublica #Buscador | P6: tc-vp-03.png | R6: Joaquin Brassinne | S6: Leonel López | T6: 46318 | U6: Búsqueda «Club Atletico» (sin tilde): 1 card, Club Atlético Río Tercero. | V6: Esperado: 2 cards. Obtenido: 1 card (Club Atlético Río Tercero). La BD real no coincide con los datos DS-01 del esperado. Se mantiene PASS.
A7: TC-VP-04 | B7: Buscar club con nombre que no existe | C7: HU-03 | D7: RF-03 | E7: CA-3.3 | F7: Partición de equivalencia (texto sin coincidencias) | G7: Verificar el estado de lista vacía al no encontrar resultados | H7: 1. Docker (PostgreSQL :5432), backend (:8080) y frontend (:5173) levantados. 2. BD cargada con el conjunto DS-01 (ver Plan de Pruebas, sección Datos de Prueba Base). | I7: nombre: xxxxxxxxxxx | J7: 1. Ir a http://localhost:5173/clubes. 2. Escribir «xxxxxxxxxxx» en el buscador. 3. Click en «Buscar». | K7: Se muestra el mensaje «No se encontraron clubes.» y 0 cards. | L7: Ninguna. | M7: PASS | N7: Media | O7: #VistaPublica #Buscador | P7: tc-vp-04.png | R7: Joaquin Brassinne | S7: Leonel López | T7: 46318 | U7: Se muestra «No se encontraron clubes».
A8: TC-VP-05 | B8: Filtrar clubes por deporte inclusivo | C8: HU-04 | D8: RF-04 | E8: CA-4.1 | F8: Partición de equivalencia (deporteAdaptado true / false) | G8: Verificar que el toggle muestra solo clubes con deporteAdaptado=true | H8: 1. Docker (PostgreSQL :5432), backend (:8080) y frontend (:5173) levantados. 2. BD cargada con el conjunto DS-01 (ver Plan de Pruebas, sección Datos de Prueba Base). | I8: Ninguno (en DS-01 solo «Club Náutico Río Tercero» tiene deporteAdaptado=true) | J8: 1. Ir a http://localhost:5173/clubes. 2. Click en el botón «Deporte Inclusivo». | K8: Se muestra exactamente 1 card: «Club Náutico Río Tercero». El botón queda visualmente activo. | L8: Ninguna. | M8: PASS | N8: Alta | O8: #VistaPublica #FiltroInclusivo #Regresion | P8: tc-vp-05.png | R8: Joaquin Brassinne | S8: Leonel López | T8: 46318 | U8: Con el filtro Deporte Inclusivo activo: 1 card, Polideportivo Municipal. | V8: Revisar: el resultado esperado usa los datos DS-01 y la BD real tiene otros datos (clubes: Club Sportivo 9 de Julio, Club Atlético Río Tercero, Polideportivo Municipal). Confirmar si el caso se mantiene en PASS.
A9: TC-VP-06 | B9: Desactivar el filtro de deporte inclusivo | C9: HU-04 | D9: RF-04 | E9: CA-4.2 | F9: Partición de equivalencia (filtro activo / inactivo) | G9: Verificar que al volver a clickear el toggle se muestran todos los clubes | H9: 1. Docker (PostgreSQL :5432), backend (:8080) y frontend (:5173) levantados. 2. BD cargada con el conjunto DS-01 (ver Plan de Pruebas, sección Datos de Prueba Base). 3. Filtro «Deporte Inclusivo» activo en /clubes (TC-VP-05 paso 2). | I9: Ninguno | J9: 1. Con el filtro activo en /clubes, click nuevamente en «Deporte Inclusivo». | K9: Se muestran los 3 clubes aprobados (Río Tercero, Náutico, Sur). El botón vuelve al estado inactivo. | L9: Ninguna. | M9: PASS | N9: Media | O9: #VistaPublica #FiltroInclusivo | P9: tc-vp-06.png | R9: Joaquin Brassinne | S9: Leonel López | T9: 46318 | U9: Con el filtro desactivado se muestran 3 clubes (Club Sportivo 9 de Julio, Club Atlético Río Tercero, Polideportivo Municipal) y el botón queda inactivo.
A10: TC-VP-07 | B10: Buscar deportista por deporte | C10: HU-09 | D10: RF-14 | E10: CA-9.1 | F10: Partición de equivalencia (deporte con / sin coincidencias) | G10: Verificar que el buscador filtra deportistas por deporte | H10: 1. Docker (PostgreSQL :5432), backend (:8080) y frontend (:5173) levantados. 2. BD cargada con el conjunto DS-01 (ver Plan de Pruebas, sección Datos de Prueba Base). | I10: deporte: Fútbol | J10: 1. Ir a http://localhost:5173/deportistas. 2. Escribir «Fútbol» en el buscador. 3. Click en «Buscar». | K10: Se muestran exactamente 2 cards: Lucía Pérez y Sofía Díaz. No se muestran Mateo Gómez ni Tomás Ruiz. | L10: Ninguna. | M10: PASS | N10: Alta | O10: #VistaPublica #Buscador | P10: tc-vp-07.png | R10: Joaquin Brassinne | S10: Leonel López | T10: 46318 | U10: Búsqueda «Fútbol» en /deportistas: «No se encontraron deportistas». | V10: Esperado: 2 deportistas. Obtenido: «No se encontraron deportistas». La BD real no coincide con los datos DS-01 del esperado. Se mantiene PASS.
A11: TC-VP-08 | B11: Estadísticas del home coinciden con la base de datos | C11: HU-08 | D11: RF-13 | E11: CA-8.1 | F11: Partición de equivalencia / verificación contra BD | G11: Verificar que los 4 contadores del home muestran el conteo real de la BD | H11: 1. Docker (PostgreSQL :5432), backend (:8080) y frontend (:5173) levantados. 2. BD cargada con el conjunto DS-01 (ver Plan de Pruebas, sección Datos de Prueba Base). 3. TablePlus conectado a la BD. | I11: Consultas de verificación (ajustar nombre de columna si difiere): SELECT COUNT(*) FROM clubs; → 3 SELECT COUNT(*) FROM deportistas; → 4 SELECT COUNT(*) FROM clubs WHERE deporte_adaptado = true; → 1 Disciplinas distintas entre perfiles aprobados → 3 (Fútbol, Básquet, Natación) | J11: 1. Ejecutar las consultas en TablePlus y anotar los valores. 2. Ir a http://localhost:5173/. 3. Leer los 4 contadores. | K11: Clubes = 3, Deportistas = 4, Disciplinas = 3, Deporte Inclusivo = 1, iguales a los valores de la BD. Ningún contador muestra «—». | L11: Ninguna. | M11: PASS | N11: Alta | O11: #Home #Integracion | P11: tc-vp-08.png | R11: Joaquin Brassinne | S11: Leonel López | T11: 46318 | U11: Contadores del home: Clubes 4, Deportistas 8, Disciplinas 13, Deporte Inclusivo 1. | V11: Contador del home: 4 clubes. La captura de /clubes muestra 3 cards. Se mantiene PASS.
A12: TC-VP-09 | B12: Pills de disciplinas filtran deportistas del home | C12: HU-09 | D12: RF-14 | E12: CA-9.3 | F12: Partición de equivalencia (disciplina con / sin deportistas) | G12: Verificar que al clickear una pill se filtran los deportistas destacados de esa disciplina | H12: 1. Docker (PostgreSQL :5432), backend (:8080) y frontend (:5173) levantados. 2. BD cargada con el conjunto DS-01 (ver Plan de Pruebas, sección Datos de Prueba Base). | I12: disciplina: Fútbol | J12: 1. Ir a http://localhost:5173/. 2. Click en la pill «Fútbol» de la sección de destacados. | K12: Se muestran exactamente 2 deportistas: Lucía Pérez y Sofía Díaz. No se muestran Mateo Gómez ni Tomás Ruiz. | L12: Ninguna. | M12: PASS | N12: Media | O12: #Home #FiltroDisciplina | P12: tc-vp-09.png | R12: Joaquin Brassinne | S12: Leonel López | T12: 46318 | U12: Al hacer click en la pill «Fútbol» no se muestran deportistas: no hay deportistas de Fútbol cargados en la BD. | V12: El filtro funciona; los deportistas se muestran cuando se cargan datos de esa disciplina. El esperado usa los datos DS-01 (no coinciden con la BD real).
A13: TC-VP-10 | B13: Búsqueda de deportista sin distinguir tildes | C13: HU-09 | D13: RF-14 | E13: CA-9.2 | F13: Partición de equivalencia (con / sin tilde) | G13: Verificar que buscar «Futbol» encuentra deportistas cuyo dato en BD es «Fútbol» | H13: 1. Docker (PostgreSQL :5432), backend (:8080) y frontend (:5173) levantados. 2. BD cargada con el conjunto DS-01 (ver Plan de Pruebas, sección Datos de Prueba Base). | I13: deporte: Futbol (sin tilde). En la BD figura «Fútbol» (con tilde) | J13: 1. Ir a http://localhost:5173/deportistas. 2. Escribir «Futbol» sin tilde. 3. Click en «Buscar». | K13: Se muestran exactamente 2 cards: Lucía Pérez y Sofía Díaz (mismo resultado que TC-VP-07). | L13: Ninguna. | M13: PASS | N13: Media | O13: #VistaPublica #Normalizacion | P13: tc-vp-10.png | R13: Joaquin Brassinne | S13: Leonel López | T13: 46318 | U13: Búsqueda «Futbol» (sin tilde) en /deportistas: «No se encontraron deportistas». | V13: Revisar: el resultado esperado usa los datos DS-01 y la BD real tiene otros datos (clubes: Club Sportivo 9 de Julio, Club Atlético Río Tercero, Polideportivo Municipal). Confirmar si el caso se mantiene en PASS.
A14: TC-VP-11 | B14: Buscar club por disciplina | C14: HU-03 | D14: RF-03 | E14: CA-3.2 | F14: Partición de equivalencia (campo disciplina) | G14: Verificar que el buscador de clubes también filtra por disciplina (RF-03) | H14: 1. Docker (PostgreSQL :5432), backend (:8080) y frontend (:5173) levantados. 2. BD cargada con el conjunto DS-01 (ver Plan de Pruebas, sección Datos de Prueba Base). | I14: disciplina: Natación | J14: 1. Ir a http://localhost:5173/clubes. 2. Escribir «Natación» en el buscador. 3. Click en «Buscar». | K14: Se muestra exactamente 1 card: «Club Náutico Río Tercero». No se muestran los otros 2 clubes. | L14: Ninguna. | M14: PASS | N14: Alta | O14: #VistaPublica #Buscador | P14: tc-vp-11.png | R14: Joaquin Brassinne | S14: Leonel López | T14: 46318 | U14: Búsqueda «Natación» en /clubes: «No se encontraron clubes». | V14: Revisar: el resultado esperado usa los datos DS-01 y la BD real tiene otros datos (clubes: Club Sportivo 9 de Julio, Club Atlético Río Tercero, Polideportivo Municipal). Confirmar si el caso se mantiene en PASS.
A15: TC-VP-12 | B15: Búsqueda de club sin distinguir mayúsculas/minúsculas | C15: HU-03 | D15: RF-03 | E15: CA-3.4 | F15: Partición de equivalencia (mayúsculas / minúsculas) | G15: Verificar que «club atlético» en minúsculas devuelve lo mismo que «Club Atlético» | H15: 1. Docker (PostgreSQL :5432), backend (:8080) y frontend (:5173) levantados. 2. BD cargada con el conjunto DS-01 (ver Plan de Pruebas, sección Datos de Prueba Base). | I15: nombre: club atlético (minúsculas) | J15: 1. Ir a http://localhost:5173/clubes. 2. Escribir «club atlético» en minúsculas. 3. Click en «Buscar». | K15: Se muestran exactamente 2 cards: «Club Atlético Río Tercero» y «Club Atlético Sur» (mismo resultado que TC-VP-03). | L15: Ninguna. | M15: PASS | N15: Media | O15: #VistaPublica #Buscador | P15: tc-vp-12.png | R15: Joaquin Brassinne | S15: Leonel López | T15: 46318 | U15: Búsqueda «club atlético» en minúsculas: 1 card, Club Atlético Río Tercero. | V15: Revisar: el resultado esperado usa los datos DS-01 y la BD real tiene otros datos (clubes: Club Sportivo 9 de Julio, Club Atlético Río Tercero, Polideportivo Municipal). Confirmar si el caso se mantiene en PASS.
A16: TC-VP-13 | B16: Un club pendiente no aparece en la búsqueda pública | C16: HU-03 | D16: RF-03 | E16: CA-3.5 | F16: Partición de equivalencia (estado de la solicitud) | G16: Verificar que los clubes en estado PENDIENTE no se devuelven aunque coincidan con la búsqueda | H16: 1. Docker (PostgreSQL :5432), backend (:8080) y frontend (:5173) levantados. 2. BD cargada con el conjunto DS-01 (ver Plan de Pruebas, sección Datos de Prueba Base). 3. Verificar en TablePlus: SELECT estado FROM solicitudes_registro WHERE tipo='CLUB' → 2 filas PENDIENTE (Club Pendiente Uno y Dos). | I16: nombre: Club Pendiente | J16: 1. Ir a http://localhost:5173/clubes. 2. Escribir «Club Pendiente» en el buscador. 3. Click en «Buscar». 4. Abrir DevTools → Network y revisar la respuesta de la petición de búsqueda. | K16: Se muestra «No se encontraron clubes.» y 0 cards. La respuesta de la API no contiene «Club Pendiente Uno» ni «Club Pendiente Dos». | L16: Ninguna. | M16: PASS | N16: Crítica | O16: #VistaPublica #Buscador #Seguridad | P16: tc-vp-13.png | R16: Joaquin Brassinne | S16: Leonel López | T16: 46318 | U16: Búsqueda «Club Pendiente»: se muestra «No se encontraron clubes.» y 0 cards. Cumple lo esperado.
A17: TC-VP-14 | B17: Búsqueda vacía muestra todos los clubes aprobados | C17: HU-03 | D17: RF-03 | E17: CA-1.1 | F17: Partición de equivalencia (entrada vacía) | G17: Verificar el comportamiento al buscar con el campo vacío | H17: 1. Docker (PostgreSQL :5432), backend (:8080) y frontend (:5173) levantados. 2. BD cargada con el conjunto DS-01 (ver Plan de Pruebas, sección Datos de Prueba Base). | I17: nombre: (vacío) | J17: 1. Ir a http://localhost:5173/clubes. 2. Escribir «Club Atlético» y buscar (quedan 2 cards). 3. Borrar el texto del buscador dejándolo vacío. 4. Click en «Buscar». | K17: Se muestran los 3 clubes aprobados. No aparece error en pantalla ni en la consola de DevTools. | L17: Ninguna. | M17: PASS | N17: Baja | O17: #VistaPublica #Buscador | P17: tc-vp-14.png | R17: Joaquin Brassinne | S17: Leonel López | T17: 46318 | U17: Con el buscador vacío se muestran los clubes (Club Sportivo 9 de Julio, Club Atlético Río Tercero, Polideportivo Municipal).
A18: TC-VP-15 | B18: Buscador ante caracteres especiales e intento de inyección SQL | C18: HU-03 | D18: RF-03 | E18: CA-3.6 | F18: Adivinanza de errores | G18: Verificar que entradas maliciosas no rompen la búsqueda ni alteran los datos | H18: 1. Docker (PostgreSQL :5432), backend (:8080) y frontend (:5173) levantados. 2. BD cargada con el conjunto DS-01 (ver Plan de Pruebas, sección Datos de Prueba Base). 3. TablePlus conectado a la BD. | I18: nombre: ' OR 1=1 -- (segunda ejecución con: @#$%&*) | J18: 1. Ir a http://localhost:5173/clubes. 2. Escribir «' OR 1=1 --» y click en «Buscar». 3. Revisar en DevTools → Network el código HTTP de la petición. 4. Repetir con «@#$%&*». 5. En TablePlus ejecutar SELECT COUNT(*) FROM clubs; | K18: Pasos 2 y 4: se muestra «No se encontraron clubes.» (no se devuelven los 3 clubes ni aparece error). Paso 3: HTTP 200, nunca 500. Paso 5: el conteo sigue siendo 3. | L18: Ninguna. | M18: PASS | N18: Alta | O18: #VistaPublica #Buscador #Seguridad | P18: tc-vp-15.png | R18: Joaquin Brassinne | S18: Leonel López | T18: 46318 | U18: Búsqueda «' OR 1=1 --»: «No se encontraron clubes»; sin error visible en pantalla.
A19: TC-VP-16 | B19: Filtro inclusivo combinado con búsqueda por nombre | C19: HU-04 | D19: RF-04 | E19: CA-4.3 | F19: Tabla de decisión (filtro inclusivo × búsqueda) | G19: Verificar la intersección entre el filtro «Deporte Inclusivo» y el buscador | H19: 1. Docker (PostgreSQL :5432), backend (:8080) y frontend (:5173) levantados. 2. BD cargada con el conjunto DS-01 (ver Plan de Pruebas, sección Datos de Prueba Base). | I19: Filtro: Deporte Inclusivo activo; nombre: Club Atlético | J19: 1. Ir a http://localhost:5173/clubes. 2. Click en «Deporte Inclusivo». 3. Escribir «Club Atlético» y click en «Buscar». 4. Desactivar el filtro (click en «Deporte Inclusivo»). | K19: Paso 3: «No se encontraron clubes.» (ningún club inclusivo contiene «Club Atlético»). Paso 4: se muestran los 2 clubes «Club Atlético Río Tercero» y «Club Atlético Sur». | L19: Ninguna. | M19: PASS | N19: Media | O19: #VistaPublica #FiltroInclusivo #Buscador | P19: tc-vp-16.png | R19: Joaquin Brassinne | S19: Leonel López | T19: 46318 | U19: Con el filtro inclusivo activo y «club atletico»: «No se encontraron clubes»; al desactivar el filtro aparece 1 card (Club Atlético Río Tercero). | V19: tc-vp-16,v2.png Revisar: el resultado esperado usa los datos DS-01 y la BD real tiene otros datos (clubes: Club Sportivo 9 de Julio, Club Atlético Río Tercero, Polideportivo Municipal). Confirmar si el caso se mantiene en PASS.

Sheet Solicitud de Registro
A1: Locos del Deporte — CrazySports (Grupo 6)
A2: Nombre del Módulo: Solicitud de Registro
A3: ID | B3: Título | C3: HU | D3: RF | E3: Criterio de aceptación | F3: Técnica de diseño | G3: Descripción | H3: Precondiciones | I3: Datos de prueba | J3: Pasos | K3: Resultado esperado | L3: Postcondición / limpieza | M3: Status | N3: Prioridad | O3: #Etiquetas | P3: Evidencia (link) | Q3: Bug (link a Issue) | R3: Diseñado por | S3: Ejecutado por | T3: Fecha de ejecución | U3: Resultado obtenido | V3: Comentarios
A4: TC-SR-01 | B4: Enviar solicitud de club con datos válidos | C4: HU-05 | D4: RF-05 | E4: CA-5.1 | F4: Partición de equivalencia (datos válidos) | G4: Un club envía su solicitud y queda en PENDIENTE | H4: 1. Docker (PostgreSQL :5432) y backend (:8080) levantados. 2. BD cargada con DS-01 (ver Plan de Pruebas, «Datos de Prueba Base»). 3. Swagger UI abierto en http://localhost:8080/swagger-ui.html. | I4: Body: {"tipo": "CLUB", "datosAdjuntos": "{\"nombreInstitucion\": \"Club Test SR01\", \"direccion\": \"Av. Test 123\", \"telefono\": \"3571000000\", \"email\": \"test@test.com\", \"disciplinas\": \"Fútbol\", \"deporteAdaptado\": false, \"fotos\": []}"} | J4: 1. En Swagger abrir POST /api/solicitudes → Try it out. 2. Pegar el body indicado. 3. Execute; registrar código y body de respuesta; anotar el id ({idSol}). 4. En TablePlus: SELECT estado FROM solicitudes_registro WHERE id = {idSol}; | K4: Paso 3: HTTP 201; body con id numérico no nulo, tipo = "CLUB", estado = "PENDIENTE" y fechaEnvio con timestamp no nulo. Paso 4: 1 fila con estado PENDIENTE. | L4: Limpieza: DELETE FROM solicitudes_registro WHERE id = {idSol}; (la solicitud «Club Test SR01»). | M4: PASS | N4: Crítica | O4: #Solicitud #Smoke | P4: tc-sr-01.png | R4: Damián Buscemi | S4: Leonel López | T4: 46318 | U4: HTTP 201 con id, tipo CLUB, estado PENDIENTE y fechaEnvio. La BD muestra 1 fila PENDIENTE.
A5: TC-SR-02 | B5: Enviar solicitud de deportista con datos válidos | C5: HU-05 | D5: RF-06 | E5: CA-5.1 | F5: Partición de equivalencia (datos válidos) | G5: Un deportista envía su solicitud y queda en PENDIENTE | H5: 1. Docker (PostgreSQL :5432) y backend (:8080) levantados. 2. BD cargada con DS-01 (ver Plan de Pruebas, «Datos de Prueba Base»). 3. Swagger UI abierto en http://localhost:8080/swagger-ui.html. | I5: Body: {"tipo": "DEPORTISTA", "datosAdjuntos": "{\"nombre\": \"Deportista Test SR02\", \"deporte\": \"Fútbol\", \"edad\": 25, \"historia\": \"Historia de prueba\", \"logros\": \"Campeón local 2024\", \"deporteAdaptado\": false, \"fotos\": [], \"clubId\": null}"} | J5: 1. POST /api/solicitudes → Try it out. 2. Pegar el body indicado. 3. Execute; registrar código y body; anotar el id ({idSol}). 4. En TablePlus: SELECT estado FROM solicitudes_registro WHERE id = {idSol}; | K5: Paso 3: HTTP 201; id numérico no nulo, tipo = "DEPORTISTA", estado = "PENDIENTE". Paso 4: 1 fila con estado PENDIENTE. | L5: Limpieza: DELETE FROM solicitudes_registro WHERE id = {idSol}; (la solicitud «Deportista Test SR02»). | M5: PASS | N5: Alta | O5: #Solicitud #Smoke | P5: tc-sr-02.png | R5: Damián Buscemi | S5: Leonel López | T5: 46318 | U5: HTTP 201 con id, tipo DEPORTISTA y estado PENDIENTE. La BD muestra 1 fila PENDIENTE.
A6: TC-SR-03 | B6: Rechazar solicitud con tipo nulo | C6: HU-05 | D6: RF-05 | E6: CA-5.2 | F6: Partición de equivalencia (campo obligatorio nulo) | G6: El sistema rechaza una solicitud sin tipo y no la guarda | H6: 1. Docker (PostgreSQL :5432) y backend (:8080) levantados. 2. BD cargada con DS-01 (ver Plan de Pruebas, «Datos de Prueba Base»). 3. Swagger UI abierto en http://localhost:8080/swagger-ui.html. 4. En TablePlus: SELECT COUNT(*) FROM solicitudes_registro; anotar el valor ({n0}). | I6: Body: {"tipo": null, "datosAdjuntos": "{\"nombreInstitucion\": \"Club Test SR03\"}"} | J6: 1. POST /api/solicitudes → Try it out. 2. Pegar el body indicado. 3. Execute; registrar código y body de error. 4. En TablePlus: SELECT COUNT(*) FROM solicitudes_registro; | K6: Paso 3: HTTP 400; el body de error menciona el campo «tipo». Paso 4: el conteo es igual a {n0} (no se creó ninguna fila). | L6: Ninguna. | M6: PASS | N6: Alta | O6: #Solicitud #Validacion | P6: tc-sr-03.png | R6: Damián Buscemi | S6: Leonel López | T6: 46318 | U6: HTTP 400 mencionando el campo «tipo». No se creó ninguna fila.
A7: TC-SR-04 | B7: Rechazar solicitud con datosAdjuntos vacío | C7: HU-05 | D7: RF-05 | E7: CA-5.2 | F7: Partición de equivalencia (campo obligatorio vacío) | G7: El sistema rechaza una solicitud sin contenido de formulario | H7: 1. Docker (PostgreSQL :5432) y backend (:8080) levantados. 2. BD cargada con DS-01 (ver Plan de Pruebas, «Datos de Prueba Base»). 3. Swagger UI abierto en http://localhost:8080/swagger-ui.html. 4. Anotar SELECT COUNT(*) FROM solicitudes_registro; ({n0}). | I7: Body: {"tipo": "CLUB", "datosAdjuntos": ""} | J7: 1. POST /api/solicitudes → Try it out. 2. Pegar el body indicado. 3. Execute; registrar código y body de error. 4. Repetir el conteo en TablePlus. | K7: Paso 3: HTTP 400; el body de error menciona el campo «datosAdjuntos». Paso 4: conteo igual a {n0}. | L7: Ninguna. | M7: PASS | N7: Alta | O7: #Solicitud #Validacion | P7: tc-sr-04.png | R7: Damián Buscemi | S7: Leonel López | T7: 46318 | U7: HTTP 400 mencionando «datosAdjuntos». No se creó ninguna fila.
A8: TC-SR-05 | B8: Toda solicitud nueva queda PENDIENTE y sin revisión | C8: HU-05 | D8: RF-07 | E8: CA-5.1 | F8: Transición de estados (estado inicial) | G8: La solicitud recién creada tiene estado PENDIENTE, fechaRevision y perfilCreadoId nulos | H8: 1. Docker (PostgreSQL :5432) y backend (:8080) levantados. 2. BD cargada con DS-01 (ver Plan de Pruebas, «Datos de Prueba Base»). 3. Swagger UI abierto en http://localhost:8080/swagger-ui.html. 4. Ejecutar TC-SR-01 y anotar el id ({idSol}). 5. Autenticación: Pulsar Authorize en Swagger e ingresar AdminRoot / locos1234. | I8: Credenciales: AdminRoot / locos1234; id: {idSol} | J8: 1. Abrir GET /api/solicitudes/{id} → Try it out. 2. Ingresar id = {idSol}; Execute. 3. En TablePlus: SELECT estado, fecha_revision, perfil_creado_id FROM solicitudes_registro WHERE id = {idSol}; | K8: Paso 2: HTTP 200; estado = "PENDIENTE", fechaRevision = null, perfilCreadoId = null. Paso 3: estado PENDIENTE, fecha_revision y perfil_creado_id NULL. | L8: Limpieza: DELETE FROM solicitudes_registro WHERE id = {idSol}; (la solicitud «Club Test SR01»). | M8: PASS | N8: Crítica | O8: #Solicitud #Estado | P8: tc-sr-05.png | R8: Damián Buscemi | S8: Leonel López | T8: 46318 | U8: HTTP 200 con estado PENDIENTE, fechaRevision y perfilCreadoId nulos. La BD coincide.
A9: TC-SR-06 | B9: El envío de solicitudes es público (sin credenciales) | C9: HU-05 | D9: RF-05 | E9: CA-5.1 | F9: Partición de equivalencia (con / sin autenticación) | G9: Cualquier persona puede enviar una solicitud sin autenticarse | H9: 1. Docker (PostgreSQL :5432) y backend (:8080) levantados. 2. BD cargada con DS-01 (ver Plan de Pruebas, «Datos de Prueba Base»). 3. Swagger UI abierto en http://localhost:8080/swagger-ui.html. 4. Asegurarse de no estar autorizado en Swagger (Authorize → Logout). | I9: Body: {"tipo": "CLUB", "datosAdjuntos": "{\"nombreInstitucion\": \"Club Test SR06\", \"direccion\": \"Av. Test 123\", \"telefono\": \"3571000000\", \"email\": \"test@test.com\", \"disciplinas\": \"Fútbol\", \"deporteAdaptado\": false, \"fotos\": []}"} | J9: 1. POST /api/solicitudes → Try it out, sin Authorization. 2. Pegar el body indicado. 3. Execute; anotar el id ({idSol}). | K9: HTTP 201; la solicitud se crea con estado = "PENDIENTE" sin pedir credenciales (no hay respuesta 401). | L9: Limpieza: DELETE FROM solicitudes_registro WHERE id = {idSol}; (la solicitud «Club Test SR06»). | M9: PASS | N9: Alta | O9: #Solicitud #Seguridad | P9: tc-sr-06.png | R9: Damián Buscemi | S9: Leonel López | T9: 46318 | U9: HTTP 201 sin credenciales (sin 401). La solicitud quedó PENDIENTE.
A10: TC-SR-07 | B10: Rechazar solicitud con tipo fuera del enum | C10: HU-05 | D10: RF-05 | E10: CA-5.2 | F10: Partición de equivalencia (valor inexistente en el enum) | G10: Un tipo que no es CLUB ni DEPORTISTA se rechaza | H10: 1. Docker (PostgreSQL :5432) y backend (:8080) levantados. 2. BD cargada con DS-01 (ver Plan de Pruebas, «Datos de Prueba Base»). 3. Swagger UI abierto en http://localhost:8080/swagger-ui.html. 4. Anotar SELECT COUNT(*) FROM solicitudes_registro; ({n0}). | I10: Body: {"tipo": "EQUIPO", "datosAdjuntos": "{\"nombreInstitucion\": \"Club Test SR07\"}"} | J10: 1. POST /api/solicitudes → Try it out. 2. Pegar el body indicado. 3. Execute; registrar código y body. 4. Repetir el conteo en TablePlus. | K10: Paso 3: HTTP 400. Paso 4: conteo igual a {n0}. | L10: Ninguna. | M10: PASS | N10: Media | O10: #Solicitud #Validacion | P10: tc-sr-07.png | R10: Damián Buscemi | S10: Leonel López | T10: 46318 | U10: HTTP 400. No se creó ninguna fila.
A11: TC-SR-08 | B11: Rechazar solicitud con datosAdjuntos JSON malformado | C11: HU-05 | D11: RF-05 | E11: CA-5.2 | F11: Adivinanza de errores | G11: Un datosAdjuntos que no es JSON válido no debe guardarse | H11: 1. Docker (PostgreSQL :5432) y backend (:8080) levantados. 2. BD cargada con DS-01 (ver Plan de Pruebas, «Datos de Prueba Base»). 3. Swagger UI abierto en http://localhost:8080/swagger-ui.html. 4. Anotar SELECT COUNT(*) FROM solicitudes_registro; ({n0}). | I11: Body: {"tipo": "CLUB", "datosAdjuntos": "{\"nombreInstitucion\":\"Club Test SR08\","} | J11: 1. POST /api/solicitudes → Try it out. 2. Pegar el body indicado. 3. Execute; registrar código y body. 4. Repetir el conteo en TablePlus. | K11: Paso 3: HTTP 400. Paso 4: conteo igual a {n0}. | L11: Ninguna. | M11: PASS | N11: Alta | O11: #Solicitud #Validacion | P11: tc-sr-08.png | R11: Damián Buscemi | S11: Leonel López | T11: 46318 | U11: HTTP 400. No se creó ninguna fila.
A12: TC-SR-09 | B12: Rechazar solicitud con datosAdjuntos nulo | C12: HU-05 | D12: RF-05 | E12: CA-5.2 | F12: Partición de equivalencia (nulo) | G12: datosAdjuntos null se rechaza | H12: 1. Docker (PostgreSQL :5432) y backend (:8080) levantados. 2. BD cargada con DS-01 (ver Plan de Pruebas, «Datos de Prueba Base»). 3. Swagger UI abierto en http://localhost:8080/swagger-ui.html. 4. Anotar SELECT COUNT(*) FROM solicitudes_registro; ({n0}). | I12: Body: {"tipo": "CLUB", "datosAdjuntos": null} | J12: 1. POST /api/solicitudes → Try it out. 2. Pegar el body. 3. Execute. 4. Repetir el conteo. | K12: Paso 3: HTTP 400; el error menciona «datosAdjuntos». Paso 4: conteo igual a {n0}. | L12: Ninguna. | M12: PASS | N12: Media | O12: #Solicitud #Validacion | P12: tc-sr-09.png | R12: Damián Buscemi | S12: Leonel López | T12: 46318 | U12: HTTP 400 mencionando «datosAdjuntos». No se creó ninguna fila.
A13: TC-SR-10 | B13: Rechazar solicitud con cuerpo vacío | C13: HU-05 | D13: RF-05 | E13: CA-5.2 | F13: Adivinanza de errores | G13: Un body {} no genera solicitud ni error 500 | H13: 1. Docker (PostgreSQL :5432) y backend (:8080) levantados. 2. BD cargada con DS-01 (ver Plan de Pruebas, «Datos de Prueba Base»). 3. Swagger UI abierto en http://localhost:8080/swagger-ui.html. 4. Anotar SELECT COUNT(*) FROM solicitudes_registro; ({n0}). | I13: Body: {} | J13: 1. POST /api/solicitudes → Try it out. 2. Pegar el body {}. 3. Execute; registrar código. 4. Repetir el conteo. | K13: Paso 3: HTTP 400 (nunca 500). Paso 4: conteo igual a {n0}. | L13: Ninguna. | M13: PASS | N13: Baja | O13: #Solicitud #Validacion | P13: tc-sr-10.png | R13: Damián Buscemi | S13: Leonel López | T13: 46318 | U13: HTTP 400 (no 500). No se creó ninguna fila.

Sheet Autenticación
A1: Locos del Deporte — CrazySports (Grupo 6)
A2: Nombre del Módulo: Autenticación
A3: ID | B3: Título | C3: HU | D3: RF | E3: Criterio de aceptación | F3: Técnica de diseño | G3: Descripción | H3: Precondiciones | I3: Datos de prueba | J3: Pasos | K3: Resultado esperado | L3: Postcondición / limpieza | M3: Status | N3: Prioridad | O3: #Etiquetas | P3: Evidencia (link) | Q3: Bug (link a Issue) | R3: Diseñado por | S3: Ejecutado por | T3: Fecha de ejecución | U3: Resultado obtenido | V3: Comentarios
A4: TC-AU-01 | B4: Acceso a endpoint protegido con credenciales válidas | C4: HU-06 | D4: RF-08 | E4: CA-6.1 | F4: Partición de equivalencia (credenciales válidas) | G4: AdminRoot accede a GET /api/solicitudes con Basic Auth | H4: 1. Docker (PostgreSQL :5432) y backend (:8080) levantados. 2. BD cargada con DS-01 (ver Plan de Pruebas, «Datos de Prueba Base»). 3. Swagger UI abierto en http://localhost:8080/swagger-ui.html. | I4: Usuario: AdminRoot; password: locos1234 (header equivalente: Authorization: Basic QWRtaW5Sb290OmxvY29zMTIzNA==) | J4: 1. Pulsar Authorize en Swagger e ingresar AdminRoot / locos1234. 2. Abrir GET /api/solicitudes → Try it out → Execute. 3. En TablePlus: SELECT COUNT(*) FROM solicitudes_registro; | K4: Paso 2: HTTP 200; el body es una lista con tantos elementos como filas devuelve el paso 3 (10 con DS-01). | L4: Ninguna. | M4: PASS | N4: Crítica | O4: #Autenticacion #Smoke #Seguridad | P4: tc-au-01.png | R4: Leonel López | S4: Leonel López | T4: 46318 | U4: HTTP 200 con la lista de solicitudes; la cantidad coincide con las filas de la BD.
A5: TC-AU-02 | B5: Acceso con contraseña incorrecta | C5: HU-06 | D5: RF-08 | E5: CA-6.1 | F5: Partición de equivalencia (password inválido) | G5: El sistema rechaza una contraseña incorrecta | H5: 1. Docker (PostgreSQL :5432) y backend (:8080) levantados. 2. BD cargada con DS-01 (ver Plan de Pruebas, «Datos de Prueba Base»). 3. Swagger UI abierto en http://localhost:8080/swagger-ui.html. | I5: Usuario: AdminRoot; password: passwordIncorrecta | J5: 1. Authorize con AdminRoot / passwordIncorrecta. 2. GET /api/solicitudes → Execute. | K5: HTTP 401; el body no contiene solicitudes. | L5: Authorize → Logout. | M5: PASS | N5: Alta | O5: #Autenticacion #Seguridad | P5: tc-au-02.png | R5: Leonel López | S5: Leonel López | T5: 46318 | U5: HTTP 401 sin solicitudes en el body.
A6: TC-AU-03 | B6: Acceso con usuario inexistente | C6: HU-06 | D6: RF-08 | E6: CA-6.1 | F6: Partición de equivalencia (usuario inválido) | G6: El sistema rechaza un usuario que no existe | H6: 1. Docker (PostgreSQL :5432) y backend (:8080) levantados. 2. BD cargada con DS-01 (ver Plan de Pruebas, «Datos de Prueba Base»). 3. Swagger UI abierto en http://localhost:8080/swagger-ui.html. | I6: Usuario: usuarioInventado; password: cualquiera | J6: 1. Authorize con usuarioInventado / cualquiera. 2. GET /api/solicitudes → Execute. | K6: HTTP 401; el body no contiene solicitudes. | L6: Authorize → Logout. | M6: PASS | N6: Alta | O6: #Autenticacion #Seguridad | P6: tc-au-03.png | R6: Leonel López | S6: Leonel López | T6: 46318 | U6: HTTP 401 sin solicitudes en el body.
A7: TC-AU-04 | B7: GET de solicitudes sin credenciales | C7: HU-06 | D7: RF-08 | E7: CA-6.1 | F7: Partición de equivalencia (sin credenciales) | G7: Un endpoint de admin no es accesible sin autenticación | H7: 1. Docker (PostgreSQL :5432) y backend (:8080) levantados. 2. BD cargada con DS-01 (ver Plan de Pruebas, «Datos de Prueba Base»). 3. Swagger UI abierto en http://localhost:8080/swagger-ui.html. 4. Asegurarse de no estar autorizado en Swagger (Authorize → Logout). | I7: Sin credenciales | J7: 1. GET /api/solicitudes → Try it out → Execute, sin Authorization. | K7: HTTP 401; el body no contiene solicitudes. | L7: Ninguna. | M7: PASS | N7: Crítica | O7: #Autenticacion #Seguridad | P7: tc-au-04.png | R7: Leonel López | S7: Leonel López | T7: 46318 | U7: HTTP 401 sin solicitudes en el body.
A8: TC-AU-05 | B8: GET /api/clubes es público | C8: HU-01 | D8: RF-01 | E8: CA-1.2 | F8: Partición de equivalencia (endpoint público) | G8: El listado de clubes no requiere autenticación | H8: 1. Docker (PostgreSQL :5432) y backend (:8080) levantados. 2. BD cargada con DS-01 (ver Plan de Pruebas, «Datos de Prueba Base»). 3. Swagger UI abierto en http://localhost:8080/swagger-ui.html. 4. Asegurarse de no estar autorizado en Swagger (Authorize → Logout). | I8: Sin credenciales | J8: 1. GET /api/clubes → Try it out → Execute, sin Authorization. | K8: HTTP 200; lista con exactamente 3 clubes: «Club Atlético Río Tercero», «Club Náutico Río Tercero» y «Club Atlético Sur». | L8: Ninguna. | M8: PASS | N8: Alta | O8: #Autenticacion #VistaPublica #Regresion | P8: tc-au-05.png | R8: Leonel López | S8: Leonel López | T8: 46318 | U8: HTTP 200 con los 3 clubes aprobados.
A9: TC-AU-06 | B9: POST de aprobación sin credenciales | C9: HU-06 | D9: RF-08 | E9: CA-6.1 | F9: Partición de equivalencia (sin credenciales) | G9: Aprobar sin autenticarse es rechazado y no crea el perfil | H9: 1. Docker (PostgreSQL :5432) y backend (:8080) levantados. 2. BD cargada con DS-01 (ver Plan de Pruebas, «Datos de Prueba Base»). 3. Swagger UI abierto en http://localhost:8080/swagger-ui.html. 4. Asegurarse de no estar autorizado en Swagger (Authorize → Logout). 5. Crear solicitud con POST /api/solicitudes y body: {"tipo": "CLUB", "datosAdjuntos": "{\"nombreInstitucion\": \"Club Test AU06\", \"direccion\": \"Av. Test 123\", \"telefono\": \"3571000000\", \"email\": \"test@test.com\", \"disciplinas\": \"Fútbol\", \"deporteAdaptado\": false, \"fotos\": []}"}; anotar el id ({idSol}). | I9: Body de aprobación: {"nombreInstitucion": "Club Test AU06", "direccion": "Av. Test 123", "telefono": "3571000000", "email": "clubtestau06@test.com", "disciplinas": "Fútbol", "deporteAdaptado": false, "fotos": []} | J9: 1. Abrir POST /api/admin/club/{id} con id = {idSol}. 2. Pegar el body de aprobación y Execute, sin Authorization. 3. En TablePlus: SELECT estado FROM solicitudes_registro WHERE id = {idSol}; y SELECT COUNT(*) FROM clubs WHERE nombre_institucion = 'Club Test AU06'; | K9: Paso 2: HTTP 401. Paso 3: estado PENDIENTE y COUNT = 0. | L9: Limpieza: DELETE FROM solicitudes_registro WHERE id = {idSol}; (la solicitud «Club Test AU06»). | M9: PASS | N9: Crítica | O9: #Autenticacion #Seguridad | P9: tc-au-06.png | R9: Leonel López | S9: Leonel López | T9: 46318 | U9: HTTP 401 sin credenciales (www-authenticate: Basic). Sin evidencia adjunta de la verificación en BD. | V9: Ruta/SQL corregidos según código fuente (v1_4).
A10: TC-AU-07 | B10: POST de rechazo sin credenciales | C10: HU-06 | D10: RF-08 | E10: CA-6.1 | F10: Partición de equivalencia (sin credenciales) | G10: Rechazar sin autenticarse es rechazado y no cambia el estado | H10: 1. Docker (PostgreSQL :5432) y backend (:8080) levantados. 2. BD cargada con DS-01 (ver Plan de Pruebas, «Datos de Prueba Base»). 3. Swagger UI abierto en http://localhost:8080/swagger-ui.html. 4. Asegurarse de no estar autorizado en Swagger (Authorize → Logout). 5. Crear solicitud con POST /api/solicitudes y body: {"tipo": "CLUB", "datosAdjuntos": "{\"nombreInstitucion\": \"Club Test AU07\", \"direccion\": \"Av. Test 123\", \"telefono\": \"3571000000\", \"email\": \"test@test.com\", \"disciplinas\": \"Fútbol\", \"deporteAdaptado\": false, \"fotos\": []}"}; anotar el id ({idSol}). | I10: id: {idSol}; motivo: prueba | J10: 1. PUT /api/admin/rechazar/{id}/prueba con id = {idSol}, sin Authorization. 2. En TablePlus: SELECT estado FROM solicitudes_registro WHERE id = {idSol}; | K10: Paso 1: HTTP 401. Paso 2: estado PENDIENTE. | L10: Limpieza: DELETE FROM solicitudes_registro WHERE id = {idSol}; (la solicitud «Club Test AU07»). | M10: PASS | N10: Alta | O10: #Autenticacion #Seguridad | P10: tc-au-07.png | R10: Leonel López | S10: Leonel López | T10: 46318 | U10: HTTP 401 sin credenciales. Sin evidencia adjunta de la verificación en BD. | V10: Ruta/SQL corregidos según código fuente (v1_4).
A11: TC-AU-08 | B11: Acceso con contraseña vacía | C11: HU-06 | D11: RF-08 | E11: CA-6.1 | F11: Valores límite (longitud 0) | G11: Una contraseña vacía se rechaza | H11: 1. Docker (PostgreSQL :5432) y backend (:8080) levantados. 2. BD cargada con DS-01 (ver Plan de Pruebas, «Datos de Prueba Base»). 3. Swagger UI abierto en http://localhost:8080/swagger-ui.html. | I11: Usuario: AdminRoot; password: (vacía) | J11: 1. Authorize con AdminRoot y password vacía. 2. GET /api/solicitudes → Execute. | K11: HTTP 401. | L11: Authorize → Logout. | M11: PASS | N11: Media | O11: #Autenticacion #Seguridad | P11: tc-au-08.png | R11: Leonel López | S11: Leonel López | T11: 46318 | U11: HTTP 401.
A12: TC-AU-09 | B12: Header Authorization malformado | C12: HU-06 | D12: RF-08 | E12: CA-6.1 | F12: Adivinanza de errores | G12: Un header Basic con contenido inválido da 401, no 500 | H12: 1. Docker (PostgreSQL :5432) y backend (:8080) levantados. 2. BD cargada con DS-01 (ver Plan de Pruebas, «Datos de Prueba Base»). 3. Swagger UI abierto en http://localhost:8080/swagger-ui.html. | I12: Header: Authorization: Basic !!! | J12: 1. En la pestaña de Swagger abrir DevTools → Console. 2. Ejecutar: fetch('/api/solicitudes',{headers:{Authorization:'Basic !!!'}}).then(r=>console.log(r.status)) | K12: La consola imprime 401 (nunca 500). | L12: Ninguna. | M12: PASS | N12: Media | O12: #Autenticacion #Seguridad | P12: tc-au-09.png | R12: Leonel López | S12: Leonel López | T12: 46318 | U12: La consola mostró 401 (no 500).
A13: TC-AU-10 | B13: GET /api/deportistas es público | C13: HU-02 | D13: RF-02 | E13: CA-2.2 | F13: Partición de equivalencia (endpoint público) | G13: El listado de deportistas no requiere autenticación | H13: 1. Docker (PostgreSQL :5432) y backend (:8080) levantados. 2. BD cargada con DS-01 (ver Plan de Pruebas, «Datos de Prueba Base»). 3. Swagger UI abierto en http://localhost:8080/swagger-ui.html. 4. Asegurarse de no estar autorizado en Swagger (Authorize → Logout). | I13: Sin credenciales | J13: 1. GET /api/deportistas → Try it out → Execute, sin Authorization. | K13: HTTP 200; lista con exactamente 4 deportistas: Lucía Pérez, Mateo Gómez, Sofía Díaz y Tomás Ruiz. | L13: Ninguna. | M13: PASS | N13: Media | O13: #Autenticacion #VistaPublica #Regresion | P13: tc-au-10.png | R13: Leonel López | S13: Leonel López | T13: 46318 | U13: HTTP 200 con los 4 deportistas aprobados.
A14: TC-AU-11 | B14: El admin por defecto se crea al iniciar el sistema | C14: HU-06 | D14: RF-08 | E14: CA-6.1 | F14: Partición de equivalencia (admin existente / inexistente) | G14: Si no hay administrador, el backend crea AdminRoot al arrancar con password cifrada | H14: 1. Docker (PostgreSQL :5432) y backend (:8080) levantados. 2. BD cargada con DS-01 (ver Plan de Pruebas, «Datos de Prueba Base»). 3. Swagger UI abierto en http://localhost:8080/swagger-ui.html. 4. TablePlus conectado a la BD. | I14: Consultas: DELETE FROM admin; SELECT COUNT(*) FROM admin; SELECT password FROM admin; | J14: 1. Detener el backend. 2. En TablePlus ejecutar DELETE FROM admin; 3. Iniciar el backend (mvn spring-boot:run). 4. Ejecutar SELECT COUNT(*) FROM admin; y SELECT password FROM admin; 5. Pulsar Authorize en Swagger e ingresar AdminRoot / locos1234. GET /api/solicitudes → Execute. | K14: Paso 4: COUNT = 1 y el password almacenado comienza con «$2» (BCrypt), no es «locos1234» en texto plano. Paso 5: HTTP 200. | L14: El admin queda creado; no requiere limpieza. | M14: PASS | N14: Alta | O14: #Autenticacion #Regresion | P14: tc-au-11.png | R14: Leonel López | S14: Leonel López | T14: 46318 | U14: El admin existe (COUNT = 1), la contraseña está hasheada con BCrypt ($2…) y el login respondió HTTP 200.

Sheet Panel de Administración
A1: Locos del Deporte — CrazySports (Grupo 6)
A2: Nombre del Módulo: Panel de Administración
A3: ID | B3: Título | C3: HU | D3: RF | E3: Criterio de aceptación | F3: Técnica de diseño | G3: Descripción | H3: Precondiciones | I3: Datos de prueba | J3: Pasos | K3: Resultado esperado | L3: Postcondición / limpieza | M3: Status | N3: Prioridad | O3: #Etiquetas | P3: Evidencia (link) | Q3: Bug (link a Issue) | R3: Diseñado por | S3: Ejecutado por | T3: Fecha de ejecución | U3: Resultado obtenido | V3: Comentarios
A4: TC-PA-01 | B4: Ver solicitudes pendientes | C4: HU-06 | D4: RF-09 | E4: CA-6.2 | F4: Partición de equivalencia (estado PENDIENTE) | G4: El admin lista solo las solicitudes PENDIENTE | H4: 1. Docker (PostgreSQL :5432) y backend (:8080) levantados. 2. BD cargada con DS-01 (ver Plan de Pruebas, «Datos de Prueba Base»). 3. Swagger UI abierto en http://localhost:8080/swagger-ui.html. 4. Autenticación: Pulsar Authorize en Swagger e ingresar AdminRoot / locos1234. 5. Ejecutar este caso antes de crear otras solicitudes (o limpiarlas). | I4: Credenciales: AdminRoot / locos1234 | J4: 1. Pulsar Authorize en Swagger e ingresar AdminRoot / locos1234. 2. GET /api/solicitudes?estado=PENDIENTE → Execute. 3. En TablePlus: SELECT COUNT(*) FROM solicitudes_registro WHERE estado = 'PENDIENTE'; | K4: Paso 2: HTTP 200; lista de exactamente 3 solicitudes, todas con estado PENDIENTE: 2 de tipo CLUB («Club Pendiente Uno», «Club Pendiente Dos») y 1 de tipo DEPORTISTA («Valentina Cruz»). Ninguna APROBADO ni RECHAZADO. Paso 3: COUNT = 3. | L4: Ninguna. | M4: PASS | N4: Crítica | O4: #Admin #Smoke | P4: tc-pa-01.png | R4: Leonel López | S4: Leonel López | T4: 46318 | U4: HTTP 200 con 3 solicitudes PENDIENTE (2 CLUB y 1 DEPORTISTA). La BD cuenta 3.
A5: TC-PA-02 | B5: Aprobar una solicitud de club pendiente crea el perfil público del club | C5: HU-06 | D5: RF-10 | E5: CA-6.3 | F5: Transición de estados (PENDIENTE → APROBADO) | G5: Aprobar crea el club, completa perfilCreadoId y lo hace visible | H5: 1. Docker (PostgreSQL :5432) y backend (:8080) levantados. 2. BD cargada con DS-01 (ver Plan de Pruebas, «Datos de Prueba Base»). 3. Swagger UI abierto en http://localhost:8080/swagger-ui.html. 4. Frontend (:5173) levantado. 5. Autenticación: Pulsar Authorize en Swagger e ingresar AdminRoot / locos1234. 6. Ejecutar TC-SR-01 con nombreInstitucion «Club Test PA02»; anotar el id ({idSol}). 7. Verificar en TablePlus: SELECT estado FROM solicitudes_registro WHERE id = {idSol}; → PENDIENTE. 8. Verificar: SELECT COUNT(*) FROM clubs WHERE nombre_institucion = 'Club Test PA02'; → 0. | I5: Credenciales: AdminRoot / locos1234 Body: {"nombreInstitucion": "Club Test PA02", "direccion": "Av. Test 123", "telefono": "3571000000", "email": "pa02@test.com", "disciplinas": "Fútbol", "deporteAdaptado": false, "fotos": []} | J5: 1. Abrir Swagger UI en http://localhost:8080/swagger-ui.html. 2. Pulsar Authorize en Swagger e ingresar AdminRoot / locos1234. 3. Abrir POST /api/admin/club/{id}, completar id = {idSol} y pegar el body. 4. Execute y registrar código y body de respuesta. 5. En TablePlus ejecutar las consultas de verificación (ver Resultado esperado). 6. Abrir http://localhost:5173/clubes (esperar hasta 30 s por el polling). | K5: Paso 4: HTTP 201; el body contiene id (numérico, no nulo), nombreInstitucion = "Club Test PA02" y deporteAdaptado = false. Paso 5: solicitudes_registro.estado = 'APROBADO', fechaRevision no nula y perfilCreadoId igual al id del club creado; SELECT COUNT(*) FROM clubs WHERE nombre_institucion = 'Club Test PA02' → 1. Paso 6: aparece una card «Club Test PA02» con la dirección «Av. Test 123». PASS solo si se cumplen las tres verificaciones (API, BD y UI); si falla alguna, es FAIL y se reporta un Issue con severidad Crítica. | L5: Eliminar el club y la solicitud de prueba o restaurar la BD a DS-01, para no afectar a TC-PA-06 ni a TC-VP-08: Limpieza: DELETE FROM clubs WHERE nombre_institucion = 'Club Test PA02'; DELETE FROM solicitudes_registro WHERE id = {idSol}; | M5: NOT RUN | N5: Crítica | O5: #Admin #Smoke #Integracion | P5: tc-pa-02.png | R5: Leonel López | S5: Leonel López | T5: 46318 | U5: Paso 4: HTTP 201 (id 16, nombreInstitucion «Club Test PA02»). Paso 6: la card aparece en /clubes. Falta la evidencia del paso 5 (TablePlus: estado, perfilCreadoId y COUNT). | V5: Ruta/SQL corregidos según código fuente (v1_4). Código: la vía /api/admin responde 201 y no guarda perfilCreadoId en la solicitud; el chequeo del paso 5 probablemente falle. tc-pa-02.v2.png Pendiente: completar paso 5.
A6: TC-PA-03 | B6: Aprobar una solicitud de deportista pendiente crea su perfil público | C6: HU-06 | D6: RF-10 | E6: CA-6.3 | F6: Transición de estados (PENDIENTE → APROBADO) | G6: Aprobar crea el deportista, completa perfilCreadoId y lo hace visible | H6: 1. Docker (PostgreSQL :5432) y backend (:8080) levantados. 2. BD cargada con DS-01 (ver Plan de Pruebas, «Datos de Prueba Base»). 3. Swagger UI abierto en http://localhost:8080/swagger-ui.html. 4. Frontend (:5173) levantado. 5. Autenticación: Pulsar Authorize en Swagger e ingresar AdminRoot / locos1234. 6. Crear solicitud con POST /api/solicitudes y body: {"tipo": "DEPORTISTA", "datosAdjuntos": "{\"nombre\": \"Deportista Test PA03\", \"deporte\": \"Fútbol\", \"edad\": 25, \"historia\": \"Historia de prueba\", \"logros\": \"Campeón local 2024\", \"deporteAdaptado\": false, \"fotos\": [], \"clubId\": null}"}; anotar el id ({idSol}). 7. Verificar: SELECT estado FROM solicitudes_registro WHERE id = {idSol}; → PENDIENTE y SELECT COUNT(*) FROM deportistas WHERE nombre = 'Deportista Test PA03'; → 0. | I6: Credenciales: AdminRoot / locos1234 Body: {"nombre": "Deportista Test PA03", "deporte": "Fútbol", "edad": 25, "historia": "Historia de prueba", "logros": "Campeón local 2024", "deporteAdaptado": false, "fotos": [], "clubId": null} | J6: 1. Abrir Swagger UI. 2. Pulsar Authorize en Swagger e ingresar AdminRoot / locos1234. 3. Abrir POST /api/admin/deportista/{id}, completar id = {idSol} y pegar el body. 4. Execute y registrar código y body. 5. En TablePlus ejecutar las consultas de verificación. 6. Abrir http://localhost:5173/deportistas (esperar hasta 30 s). | K6: Paso 4: HTTP 201; el body contiene id no nulo, nombre = "Deportista Test PA03", deporte = "Fútbol" y edad = 25. Paso 5: estado = 'APROBADO', fechaRevision no nula, perfilCreadoId = id del deportista; COUNT en deportista = 1. Paso 6: aparece la card «Deportista Test PA03» (Fútbol, «Campeón local 2024»). PASS solo si se cumplen las tres verificaciones; si no, FAIL con Issue de severidad Crítica. | L6: Limpieza: DELETE FROM deportistas WHERE nombre = 'Deportista Test PA03'; DELETE FROM solicitudes_registro WHERE id = {idSol}; | M6: NOT RUN | N6: Crítica | O6: #Admin #Smoke #Integracion | P6: tc-pa-03.png | R6: Leonel López | S6: Leonel López | T6: 46318 | U6: Paso 4: HTTP 201 (id 23, nombre «Deportista Test PA03»). Paso 6: la card aparece en /deportistas. Falta la evidencia del paso 5 (TablePlus). | V6: Ruta/SQL corregidos según código fuente (v1_4). Código: la vía /api/admin responde 201 y no guarda perfilCreadoId en la solicitud; el chequeo del paso 5 probablemente falle. https://drive.gotc-pa-03.v2.png Pendiente: completar paso 5.
A7: TC-PA-04 | B7: Rechazar una solicitud con motivo | C7: HU-06 | D7: RF-11 | E7: CA-6.4 | F7: Transición de estados (PENDIENTE → RECHAZADO) | G7: El admin rechaza con motivo y no se crea el perfil | H7: 1. Docker (PostgreSQL :5432) y backend (:8080) levantados. 2. BD cargada con DS-01 (ver Plan de Pruebas, «Datos de Prueba Base»). 3. Swagger UI abierto en http://localhost:8080/swagger-ui.html. 4. Autenticación: Pulsar Authorize en Swagger e ingresar AdminRoot / locos1234. 5. Crear solicitud con POST /api/solicitudes y body: {"tipo": "CLUB", "datosAdjuntos": "{\"nombreInstitucion\": \"Club Test PA04\", \"direccion\": \"Av. Test 123\", \"telefono\": \"3571000000\", \"email\": \"test@test.com\", \"disciplinas\": \"Fútbol\", \"deporteAdaptado\": false, \"fotos\": []}"}; anotar el id ({idSol}). | I7: id: {idSol}; motivo: Documentación incompleta | J7: 1. Abrir PUT /api/admin/rechazar/{id}/{motivo} → Try it out. 2. Completar id = {idSol} y motivo = Documentación incompleta; Execute. 3. En TablePlus: SELECT estado, motivo_rechazo, fecha_revision FROM solicitudes_registro WHERE id = {idSol}; y SELECT COUNT(*) FROM clubs WHERE nombre_institucion = 'Club Test PA04'; | K7: Paso 2: HTTP 200; estado = "RECHAZADO" y motivoRechazo = "Documentación incompleta". Paso 3: estado RECHAZADO, motivo_rechazo = 'Documentación incompleta', fecha_revision no nula; COUNT club = 0. | L7: Limpieza: DELETE FROM solicitudes_registro WHERE id = {idSol}; | M7: NOT RUN | N7: Alta | O7: #Admin #Estado | P7: tc-pa-04.png | R7: Leonel López | S7: Leonel López | T7: 46318 | U7: HTTP 200 con cuerpo de texto «Solicitud Rechazada» (el resultado esperado describe un JSON con estado y motivo). Falta la evidencia del paso 3 (TablePlus). | V7: Ruta/SQL corregidos según código fuente (v1_4). Pendiente: paso 3 y definir si el esperado debe cambiar.
A8: TC-PA-05 | B8: Rechazar una solicitud sin motivo | C8: HU-06 | D8: RF-11 | E8: CA-6.4 | F8: Partición de equivalencia (parámetro opcional ausente) | G8: El motivo de rechazo es opcional | H8: 1. Docker (PostgreSQL :5432) y backend (:8080) levantados. 2. BD cargada con DS-01 (ver Plan de Pruebas, «Datos de Prueba Base»). 3. Swagger UI abierto en http://localhost:8080/swagger-ui.html. 4. Autenticación: Pulsar Authorize en Swagger e ingresar AdminRoot / locos1234. 5. Crear solicitud con POST /api/solicitudes y body: {"tipo": "CLUB", "datosAdjuntos": "{\"nombreInstitucion\": \"Club Test PA05\", \"direccion\": \"Av. Test 123\", \"telefono\": \"3571000000\", \"email\": \"test@test.com\", \"disciplinas\": \"Fútbol\", \"deporteAdaptado\": false, \"fotos\": []}"}; anotar el id ({idSol}). | I8: id: {idSol}; sin parámetro motivo | J8: 1. Abrir PATCH /api/solicitudes/{id}/rechazar → Try it out. 2. Completar solo id = {idSol} (dejar motivo vacío); Execute. | K8: HTTP 200; estado = "RECHAZADO" y motivoRechazo = null. | L8: Limpieza: DELETE FROM solicitudes_registro WHERE id = {idSol}; | M8: PASS | N8: Media | O8: #Admin #Estado | P8: tc-pa-05.png | R8: Leonel López | S8: Leonel López | T8: 46318 | U8: PATCH /api/solicitudes/48/rechazar: HTTP 200; estado RECHAZADO y motivoRechazo null. Se observa además fechaEnvio actualizada y fechaRevision null. | V8: Ruta/SQL corregidos según código fuente (v1_4). Con PUT /api/admin/rechazar/{id}/{motivo} el motivo es obligatorio; se prueba por PATCH /api/solicitudes/{id}/rechazar. Ese método actualiza fechaEnvio en vez de fechaRevision (posible bug). Hallazgo: este método actualiza fechaEnvio y deja fechaRevision en null (ver captura).
A9: TC-PA-06 | B9: No se puede aprobar una solicitud ya aprobada | C9: HU-06 | D9: RF-10 | E9: CA-6.5 | F9: Transición de estados (APROBADO → APROBADO, inválida) | G9: Aprobar dos veces la misma solicitud es rechazado y no duplica el perfil | H9: 1. Docker (PostgreSQL :5432) y backend (:8080) levantados. 2. BD cargada con DS-01 (ver Plan de Pruebas, «Datos de Prueba Base»). 3. Swagger UI abierto en http://localhost:8080/swagger-ui.html. 4. Autenticación: Pulsar Authorize en Swagger e ingresar AdminRoot / locos1234. 5. Crear solicitud con POST /api/solicitudes y body: {"tipo": "CLUB", "datosAdjuntos": "{\"nombreInstitucion\": \"Club Test PA06\", \"direccion\": \"Av. Test 123\", \"telefono\": \"3571000000\", \"email\": \"test@test.com\", \"disciplinas\": \"Fútbol\", \"deporteAdaptado\": false, \"fotos\": []}"}; anotar el id ({idSol}). 6. Aprobar la solicitud una vez: POST /api/admin/club/{idSol} con el body de abajo (HTTP 200). | I9: Body: {"nombreInstitucion": "Club Test PA06", "direccion": "Av. Test 123", "telefono": "3571000000", "email": "clubtestpa06@test.com", "disciplinas": "Fútbol", "deporteAdaptado": false, "fotos": []} | J9: 1. Abrir POST /api/admin/club/{id} con id = {idSol} y el mismo body. 2. Execute y registrar código y body. 3. En TablePlus: SELECT COUNT(*) FROM clubs WHERE nombre_institucion = 'Club Test PA06'; y SELECT estado FROM solicitudes_registro WHERE id = {idSol}; | K9: Paso 2: HTTP 400; mensaje «La solicitud no es pendiente». Paso 3: COUNT club = 1 (sin duplicado) y estado sigue APROBADO. | L9: Limpieza: DELETE FROM clubs WHERE nombre_institucion = 'Club Test PA06'; DELETE FROM solicitudes_registro WHERE id = {idSol}; | M9: FAIL | N9: Alta | O9: #Admin #Validacion #Estado | P9: tc-pa-06.png | R9: Leonel López | S9: Leonel López | T9: 46318 | U9: HTTP 400 pero con mensaje «Ya existe un club con el nombre: Club Test PA06» en lugar de «La solicitud no es pendiente». | V9: Ruta/SQL corregidos según código fuente (v1_4). Indicaría que se intenta crear el club antes de validar el estado de la solicitud. Confirmar y abrir Issue.
A10: TC-PA-07 | B10: No se puede rechazar una solicitud ya rechazada | C10: HU-06 | D10: RF-11 | E10: CA-6.5 | F10: Transición de estados (RECHAZADO → RECHAZADO, inválida) | G10: Rechazar dos veces es rechazado y no modifica el motivo original | H10: 1. Docker (PostgreSQL :5432) y backend (:8080) levantados. 2. BD cargada con DS-01 (ver Plan de Pruebas, «Datos de Prueba Base»). 3. Swagger UI abierto en http://localhost:8080/swagger-ui.html. 4. Autenticación: Pulsar Authorize en Swagger e ingresar AdminRoot / locos1234. 5. Crear solicitud con POST /api/solicitudes y body: {"tipo": "CLUB", "datosAdjuntos": "{\"nombreInstitucion\": \"Club Test PA07\", \"direccion\": \"Av. Test 123\", \"telefono\": \"3571000000\", \"email\": \"test@test.com\", \"disciplinas\": \"Fútbol\", \"deporteAdaptado\": false, \"fotos\": []}"}; anotar el id ({idSol}). 6. Rechazar la solicitud una vez: PUT /api/admin/rechazar/{idSol}/Primer motivo (HTTP 200). | I10: id: {idSol}; motivo: Segundo motivo | J10: 1. PUT /api/admin/rechazar/{id}/Segundo motivo con id = {idSol}. 2. Execute y registrar código y body. 3. En TablePlus: SELECT motivo_rechazo FROM solicitudes_registro WHERE id = {idSol}; | K10: Paso 2: HTTP 400; mensaje «La solicitud no es pendiente». Paso 3: motivo_rechazo = 'Primer motivo'. | L10: Limpieza: DELETE FROM solicitudes_registro WHERE id = {idSol}; | M10: PASS | N10: Alta | O10: #Admin #Validacion #Estado | P10: tc-pa-07.png | R10: Leonel López | S10: Leonel López | T10: 46318 | U10: HTTP 400 «La solicitud no es pendiente». Se usó motivo «Tercer motivo» en lugar de «Segundo motivo». Sin evidencia adjunta de la verificación en BD. | V10: Ruta/SQL corregidos según código fuente (v1_4).
A11: TC-PA-08 | B11: Aprobar solicitud inexistente | C11: HU-06 | D11: RF-10 | E11: CA-6.5 | F11: Partición de equivalencia (id inexistente) | G11: Aprobar un id que no existe devuelve 404 y no crea nada | H11: 1. Docker (PostgreSQL :5432) y backend (:8080) levantados. 2. BD cargada con DS-01 (ver Plan de Pruebas, «Datos de Prueba Base»). 3. Swagger UI abierto en http://localhost:8080/swagger-ui.html. 4. Autenticación: Pulsar Authorize en Swagger e ingresar AdminRoot / locos1234. 5. Verificar que no existe la solicitud: SELECT COUNT(*) FROM solicitudes_registro WHERE id = 999999; → 0. | I11: id: 999999 Body: {"nombreInstitucion": "Club Test PA08", "direccion": "Av. Test 123", "telefono": "3571000000", "email": "clubtestpa08@test.com", "disciplinas": "Fútbol", "deporteAdaptado": false, "fotos": []} | J11: 1. POST /api/admin/club/{id} con id = 999999 y el body. 2. Execute. 3. En TablePlus: SELECT COUNT(*) FROM clubs WHERE nombre_institucion = 'Club Test PA08'; | K11: Paso 2: HTTP 404 (criterio del equipo: recurso inexistente = 404). Paso 3: COUNT = 0. | L11: Ninguna. | M11: FAIL | N11: Alta | O11: #Admin #Validacion | P11: tc-pa-08.png | R11: Leonel López | S11: Leonel López | T11: 46318 | U11: HTTP 400 «La solicitud con ID 999999 no existe.» (se esperaba 404). | V11: Ruta/SQL corregidos según código fuente (v1_4). Código: id inexistente devuelve 400 (IllegalArgumentException), no 404. Confirmar criterio. Mismo criterio que TC-PA-09, TC-API-03 y TC-API-07.
A12: TC-PA-09 | B12: Rechazar solicitud inexistente | C12: HU-06 | D12: RF-11 | E12: CA-6.5 | F12: Partición de equivalencia (id inexistente) | G12: Rechazar un id que no existe devuelve 404 | H12: 1. Docker (PostgreSQL :5432) y backend (:8080) levantados. 2. BD cargada con DS-01 (ver Plan de Pruebas, «Datos de Prueba Base»). 3. Swagger UI abierto en http://localhost:8080/swagger-ui.html. 4. Autenticación: Pulsar Authorize en Swagger e ingresar AdminRoot / locos1234. | I12: id: 999999; motivo: prueba | J12: 1. PUT /api/admin/rechazar/999999/prueba → Execute. | K12: HTTP 404. | L12: Ninguna. | M12: FAIL | N12: Media | O12: #Admin #Validacion | P12: tc-pa-09.png | R12: Leonel López | S12: Leonel López | T12: 46318 | U12: HTTP 400 «La solicitud con ID 999999 no existe.» (se esperaba 404). | V12: Ruta/SQL corregidos según código fuente (v1_4). Código: id inexistente devuelve 400 (IllegalArgumentException), no 404. Confirmar criterio. Mismo criterio que TC-PA-08.
